Workbook

Sheet 功能开发计划
A1: 主功能 | B1: 子项目 | C1: 完成时间 | D1: 完成 进度 | E1: 状态 | F1: 关键 commit | G1: 风险 等级 | H1: 负责人 | I1: 投入 人天 | J1: 备注 | K1: 功能说明（场景 / 怎么用）
A2: 平台基础 | B2: 上游 v1.14.0 合并 + 7 个 MR patch | C2: 2026-07-21 | D2: 100% | E2: 已发布 | F2: 2ddd91a | G2: 低 | H2: 马克群 | I2: 0.5 | J2: 基线版本，3 套环境脚手架 | K2: 【场景】公司 DBA 团队需要 SQL 审核 + 工单流平台；【使用】部署后默认进入 Archery 主界面，业务开发走标准 SQL 上线流程。
B3: 134 dev / 110 prod / staging 初始化 | C3: 2026-07-21 | D3: 100% | E3: 已发布 | F3: — | G3: 低 | H3: 马克群 | I3: 0.5 | J3: dev=9003 / prod=9123，裸机 systemd | K3: 【场景】3 套环境隔离，代码不直接动生产；【使用】每套独立 .env + systemd unit，promote_110.sh 跨环境发布。
B4: dev 部署迭代 v0.1.1 ~ v0.1.9 | C4: 2026-07-22 ~ 07-30 | D4: 100% | E4: 已发布 | F4: 8 个 commit | G4: 低 | H4: 马克群 | I4: 2 | J4: systemd 化、qcluster 配置、ARCHERY_LOG_LEVEL | K4: 【场景】dev 从手工启服务到稳定 systemd；【使用】systemctl start archery-prod-gunicorn / archery-prod-qcluster，journalctl -u 看日志。
B5: 134/110 拓扑原则定 | C5: 2026-08-03 | D5: 100% | E5: 已发布 | F5: — | G5: 低 | H5: 马克群 | I5: 0.1 | J5: 134=DEV / 110=PROD | K5: 【场景】防止误操作生产；【使用】dev 验证通过才推 prod，110 prod 仅手动 ssh 介入。
B6: promote_110.sh 发布脚本 | C6: 2026-08-04 | D6: 100% | E6: 已发布 | F6: c9236a0 | G6: 低 | H6: 马克群 | I6: 0.5 | J6: 5 phase 发布脚本 | K6: 【场景】134 dev 验证完要一键推到 110 prod；【使用】在 134 上跑 ./scripts/promote_110.sh <commit-hash>，自动 backup + fetch + adapt + deploy。
A7: 钉钉 OA 集成 | B7: 驱动可插拔架构（audit_driver 路由） | C7: 2026-08-04 | D7: 100% | E7: 已发布 | F7: abe7f66 | G7: 低 | H7: 马克群 | I7: 0.5 | J7: audit_driver 可扩展 | K7: 【场景】未来想接入企业微信 OA / 飞书审批不用改核心；【使用】DRIVER_REGISTRY 注册新 driver，admin 配置 flow.audit_driver 选新值即可。
B8: 3D policy matching 策略匹配 | C8: 2026-08-04 | D8: 100% | E8: 已发布 | F8: abe7f66 | G8: 低 | H8: 马克群 | I8: 0.5 | J8: SQL 类型∧核心表∧行数 | K8: 【场景】不同 SQL 类型 + 不同业务表 + 不同行数走不同审批；【使用】admin 维护 ext_approval_policy 多条规则，按 priority 倒序匹配。
B9: handle_oa_callback 核心（幂等去重） | C9: 2026-08-04 | D9: 100% | E9: 已发布 | F9: abe7f66 | G9: 低 | H9: 马克群 | I9: 0.5 | J9: select_for_update + 验签 | K9: 【场景】钉钉侧审批结果自动回写到 Archery 状态；【使用】钉钉推送 → /dingtalk/oa/callback → 自动推进工单 + 写 WorkflowAuditDetail。
B10: 1对1 通知端到端跑通 | C10: 2026-08-04 | D10: 100% | E10: 已发布 | F10: abe7f66 | G10: 低 | H10: 马克群 | I10: 0.3 | J10: workflow_id=4 真跑通 | K10: 【场景】审批人变更时主动通知；【使用】dingtalk_oa driver 自动调钉钉 Open API 推 1对1 消息，业务方无需手动。
B11: v0.2.0 推到 110 prod | C11: 2026-08-04 | D11: 100% | E11: 已发布 | F11: c9236a0 | G11: 中 | H11: 马克群 | I11: 1 | J11: gunicorn pid 102228 + 4 workers | K11: 【场景】134 dev 验证完成，要给生产用上钉钉 OA 框架；【使用】promote_110.sh + 110 .env 启用 OA，admin 维护流程。
B12: 110 启用 OA 框架（published-not-enabled） | C12: 2026-08-04 21:22 | D12: 100% | E12: 已发布 | F12: — | G12: 低 | H12: 马克群 | I12: 0.2 | J12: 框架就绪、暂不启用 | K12: 【场景】110 prod 先上框架、暂不启用；【使用】admin 维护 ext_approval_flow / policy，把 audit_driver 切到 dingtalk_oa 即可启用。
A13: gh-ost 无锁 DDL | B13: 设计文档（12 章节） | C13: 2026-08-05 | D13: 100% | E13: 已发布 | F13: df90b37 | G13: 低 | H13: 马克群 | I13: 0.2 | J13: docs/designs/...html | K13: 【场景】v0.3.0 要做什么 / 不做什么团队对齐；【使用】浏览器打开 docs/designs/2026-08-05_gh-ost-product-design.html，含场景、流程、验收标准。
B14: gh-ost v1.1.10 二进制装到 134 dev | C14: 2026-08-05 | D14: 100% | E14: 已发布 | F14: — | G14: 低 | H14: 马克群 | I14: 0.2 | J14: /usr/local/bin/gh-ost | K14: 【场景】dev 环境演练无锁 DDL；【使用】gh-ost --version 验证 v1.1.10；后续 Archery 调它时走 settings.CUSTOM_GH_OST_BIN。
B15: v0.3.0-alpha：ext_ddl_ghost_task 表 + admin | C15: 2026-08-06 上午 | D15: 100% | E15: 已发布 | F15: 4f34a81 | G15: 低 | H15: 马克群 | I15: 0.5 | J15: 状态机 + 进度字段 | K15: 【场景】gh-ost 任务需要持久化记录 + admin 可查；【使用】admin → 扩展表 → gh-ost 任务，能看每条 task 的状态/进度/进程/错误。
B16: v0.3.0-alpha：预检查 5 道（binlog/disk/privs/sql/table_type） | C16: 2026-08-06 上午 | D16: 100% | E16: 已发布 | F16: 4f34a81 | G16: 低 | H16: 马克群 | I16: 0.5 | J16: 只读检查 | K16: 【场景】防止 gh-ost 跑挂了（binlog 不对、磁盘不够、权限缺、SQL 不合法、源表不对）；【使用】业务方勾"启用 gh-ost"时自动跑，5/5 PASS 才允许起进程。
B17: v0.3.0-alpha：6 个 endpoint + 进度面板 | C17: 2026-08-06 上午 | D17: 100% | E17: 已发布 | F17: 4f34a81 | G17: 低 | H17: 马克群 | I17: 0.5 | J17: precheck/enable/start/cancel/status/progress | K17: 【场景】前后端交互 + 业务方看迁移进度；【使用】POST /gh_ost/{action}/<wf_id>/ 触发；GET /gh_ost/progress/<wf_id>/ 看可视化进度面板（3s 自动刷新）。
B18: v0.3.0-alpha：端到端跑通 4 个 bug 修复 | C18: 2026-08-06 上午 | D18: 100% | E18: 已发布 | F18: c0f42b3 | G18: 低 | H18: 马克群 | I18: 0.3 | J18: 4 bug | K18: 【场景】alpha 端到端要跑通；【使用】用户无感，自动修复 SqlWorkflowContent OneToOne / PARTITION_NAME 列名 / ENGINE 大小写 / .env 兜底直连。
B19: v0.3.0-beta：真启 gh-ost 子进程（runner.py） | C19: 2026-08-06 下午 | D19: 100% | E19: 已发布 | F19: 2c5a0b7 | G19: 低 | H19: 马克群 | I19: 0.3 | J19: Popen + nohup | K19: 【场景】业务方提交 ALTER TABLE 工单要真改表；【使用】业务方在工单详情勾选 gh-ost → 5/5 PASS → DBA admin 点"启动"。
B20: v0.3.0-beta：stdout 解析器（parser.py） | C20: 2026-08-06 下午 | D20: 100% | E20: 已发布 | F20: 2c5a0b7 | G20: 低 | H20: 马克群 | I20: 0.3 | J20: 1.1.10 输出兼容 | K20: 【场景】gh-ost 进程输出要可视化；【使用】poller 自动每 3s 解析 log → 写 task.progress_* → 进度面板实时更新。
B21: v0.3.0-beta：状态机自动推进（poller.py） | C21: 2026-08-06 下午 | D21: 100% | E21: 已发布 | F21: 2c5a0b7 | G21: 低 | H21: 马克群 | I21: 0.5 | J21: 3s 轮询 | K21: 【场景】gh-ost 跑完后状态要自动切到 success/failed；【使用】poller 检测进程死亡 + 解析 log 末尾 → 自动 _finalize_task 写终态。
B22: v0.3.0-beta：admin cancel / retry / rollback 3 action | C22: 2026-08-06 下午 | D22: 100% | E22: 已发布 | F22: 2c5a0b7 | G22: 低 | H22: 马克群 | I22: 0.3 | J22: DBA 介入入口 | K22: 【场景】DBA 紧急介入（取消/重试/回滚）；【使用】admin → gh-ost 任务 → 勾选 → 选 action（取消当前、重试失败、手动 drop 影子表）。
B23: v0.3.0-beta：钉钉群通知（notify.py） | C23: 2026-08-06 下午 | D23: 100% | E23: 已发布 | F23: 2c5a0b7 | G23: 低 | H23: 马克群 | I23: 0.2 | J23: best-effort | K23: 【场景】DBA 群要知道工单迁移结果；【使用】配置 110 .env 的 DINGTALK_NOTIFY_WEBHOOK，task 终态时自动 @ 发起人 + 报告耗时。
B24: v0.3.0-beta：暂停阈值（Threads_running SIGSTOP） | C24: 2026-08-06 下午 | D24: 100% | E24: 已发布 | F24: 2c5a0b7 | G24: 低 | H24: 马克群 | I24: 0.3 | J24: 生产保护 | K24: 【场景】生产高峰期不能压垮 MySQL；【使用】poller 每 10s 查 Threads_running → 超阈值 SIGSTOP gh-ost → 负载降下来 SIGCONT。
B25: v0.3.0-beta：影子表 7 天 cron | C25: 2026-08-06 下午 | D25: 100% | E25: 已发布 | F25: 2c5a0b7 | G25: 低 | H25: 马克群 | I25: 0.3 | J25: 管理命令 | K25: 【场景】失败留下的影子表越攒越多；【使用】django-q 调度 /usr/bin/python manage.py cleanup_ghost_tables（或手动跑加 --dry-run 预览）。
... B28: 提 MR6 给上游 hhyo/Archery | C28: — | D28: 0% | E28: 可选 | F28: 09d3cc2 | G28: 低 | H28: 马克群 | I28: 0.2 | J28: 5 行 diff | K28: 【场景】bigint 精度问题影响所有 1.14.0 用户；【使用】mavis PR 到 github.com/hhyo/Archery，5 行 diff（sql_api/renderers.py 加 bigint_as_string=True）。
A29: 收尾 | B29: D+7 清理 110 旧版 /dbdata/archery_v114/ | C29: 2026-08-12 后 | D29: 0% | E29: 待办 | F29: — | G29: 低 | H29: 马克群 | I29: 0.2 | J29: A 级回滚保险到期 | K29: 【场景】110 prod 旧版保留 7 天后可以清；【使用】DBA 在 2026-08-12 后跑 rm -rf /dbdata/archery_v114/ + 删 /backup/promote/switch_20260805_201046/。
B30: MR 5 MySQL 5.7 → 8.0 升级规划 | C30: — | D30: 0% | E30: TBD | F30: — | G30: 高 | H30: 马克群 | I30: 5+ | J30: 独立项目 | K30: 【场景】5.7 已 EOL，必须升级到 8.0；【使用】独立项目评估 → 语法兼容性测试 + 字符集迁移 + 复制拓扑验证 → 切流（预计 5+ 天）。
A31: gh-ost 无锁 DDL | B31: v0.4.0 列压缩 | C31: 2026-08-06 | D31: 100% | E31: 已发布 | F31: 33cfd0f | G31: 中 | H31: mavis | I31: 0.3 | J31: Excel 列压缩到 11 列；DROP COLUMN + ADD COLUMN 改写为单行 ALTER 链 | K31: 【场景】v0.3.0 之前 DROP/ADD 拆成两条工单，134 dev 演练 1 张表要走 2 次 gh-ost。【使用】工单页面检测到 DROP+ADD 同表同提交 → 合并成 `ALTER TABLE x DROP col_a, ADD col_b` 单条 → 1 次 gh-ost 完成。
A32: gh-ost 无锁 DDL | B32: v0.4.1-alpha：ArchiveConfig 加进度字段（last_archive_status + progress_pct） | C32: — | D32: 0% | E32: 待办 | F32: DRAFT | G32: 低 | H32: mavis | I32: 0.3 | J32: admin list_display 加 last_archive_status / progress_pct 字段 | K32: 【场景】现有 archive_config 表只有 last_archive_time，看不到归档是否成功、跑了多少行。【使用】新增字段 last_archive_status（success/failed/running/pending）+ progress_pct + rows_archived；admin 列表直接看到状态。
A33: gh-ost 无锁 DDL | B33: v0.4.1-alpha：归档详情页增强（archive_detail.html 进度条 + 历史日志表格） | C33: — | D33: 0% | E33: 待办 | F33: DRAFT | G33: 中 | H33: mavis | I33: 0.4 | J33: templates/sqlarchive.html 改造 + ArchiveLog 表格化 | K33: 【场景】DBA 点进归档详情只看到基础字段，看不到每次归档跑了多少行 / 用了多久 / 失败原因。【使用】详情页加 进度条 + 历史日志表格（select_cnt/insert_cnt/delete_cnt/start_time/end_time/success/error_info）。
A34: gh-ost 无锁 DDL | B34: v0.4.1-alpha：归档完成钉钉通知（ArchiveLog 写完后发） | C34: — | D34: 0% | E34: 待办 | F34: DRAFT | G34: 低 | H34: mavis | I34: 0.2 | J34: archiver.archive() 末尾 async_task 发钉钉群 | K34: 【场景】归档是异步任务，DBA 不盯着页面不知道跑完没。【使用】archive() 完成后 async_task 调 notify_terminal，发钉钉群（best-effort，webhook 没配就 skip）。
A35: gh-ost 无锁 DDL | B35: v0.4.2-alpha：ArchiveConfig 加 auto_rebuild_after_archive 字段 + 归档完成 hook | C35: — | D35: 0% | E35: 待办 | F35: DRAFT | G35: 中 | H35: mavis | I35: 0.5 | J35: Boolean 字段；archive() 成功后自动触发 v0.4.5 rebuild task | K35: 【场景】归档删完数据后表会有大量碎片，需要 OPTIMIZE/重建。以前是手动两步走。【使用】ArchiveConfig 加 auto_rebuild_after_archive Boolean（默认 False）；archive() 成功后检测字段 → 写 DdlGhostTask（task_type=rebuild, related_task_id=archive_id）。
A36: gh-ost 无锁 DDL | B36: v0.4.2-beta：134 dev 演练归档→自动回收（accesscard_black_detail 造数据） | C36: — | D36: 0% | E36: 待办 | F36: DRAFT | G36: 中 | H36: mavis | I36: 0.3 | J36: 134 dev 演练：归档 100 万行历史数据 → 验证自动 rebuild | K36: 【场景】真实业务表测归档+重建联动。【使用】DBA 在 134 dev archery_dev 库 accesscard_black_detail 灌 100 万行 → 配归档+勾 auto_rebuild → 触发归档 → 验证 rebuild 自动跑 + 碎片回收成功。
A37: gh-ost 无锁 DDL | B37: v0.4.3-alpha：ArchiveLog 前端表格化（select/insert/delete 数量可视化） | C37: — | D37: 0% | E37: 待办 | F37: DRAFT | G37: 低 | H37: mavis | I37: 0.3 | J37: archive_log.html 加可视化（条形图 / 数字徽章） | K37: 【场景】归档日志表里只有 select_cnt/insert_cnt/delete_cnt 三个数字，肉眼比对累。【使用】前端加条形图 + 颜色徽章（成功=绿/失败=红），DBA 一眼看成功率和数据量趋势。
A38: gh-ost 无锁 DDL | B38: v0.4.3-alpha：归档成功率统计 dashboard（周/月） | C38: — | D38: 0% | E38: 待办 | F38: DRAFT | G38: 低 | H38: mavis | I38: 0.3 | J38: dashboard 模块加 archive 统计卡片 | K38: 【场景】DBA 主管要看全局归档健康度。【使用】dashboard 加卡片：本周归档次数 / 成功率 / 总归档行数 / 失败 Top 5。SQL 用 SUM/COUNT GROUP BY week，django 模板渲染。
A39: 钉钉 OA 集成 | B39: v0.2.1 钉钉 OA 模板（process_code） | C39: 2026-08-06 | D39: 0% | E39: 待办 | F39: DRAFT | G39: 中 | H39: 马克群 | I39: 0.5 | J39: 未开始；用户在 oa.dingtalk.com 建模板
A40: 钉钉 OA 集成 | B40: v0.2.2 Tunnel + 回调加密（cloudflared） | C40: 2026-08-06 | D40: 0% | E40: 待办 | F40: DRAFT | G40: 中 | H40: 马克群 | I40: 1 | J40: 前置条件：DBA 需自备域名（公网已备案），不能用 trycloudflare 临时域名；callback URL 走域名 + HTTPS
A41: 钉钉 OA 集成 | B41: v0.2.3 对账 cron + runbook | C41: 2026-08-06 | D41: 0% | E41: 待办 | F41: DRAFT | G41: 中 | H41: 马克群 | I41: 1 | J41: 依赖：v0.2.1 模板 + v0.2.2 tunnel 都完成后才能做（callback 不通就没法对账）
A42: gh-ost 无锁 DDL | B42: v0.4.5-alpha：model 改造（task_type + target_table + 拆 OneToOne） | C42: 2026-08-06 | D42: 100% | E42: 已发布 | F42: 6412da4 | G42: 中 | H42: 马克群 | I42: 0.3 | J42: alpha 6 件第 1 件；134 dev makemigrations --check 0 missing + migrate --check 0 阻塞 | K42: 【场景】ghost 是工单级（OneToOne SqlWorkflow），rebuild 是表级（DBA 手动选表）。【使用】新增字段 `task_type`/`target_table`/`related_task_id`；rebuild 时 workflow=NULL，target_table 存 `db.table`。
...

Sheet 汇总统计
A1: Archery 二次开发 · 汇总统计
A3: 按主功能统计
A4: 主功能 | B4: 子项目数 | C4: 已完成 | D4: 完成率 | E4: 高风险数 | F4: 投入人天
A5: 平台基础 | B5: =COUNTIF(功能开发计划!A:A,A5) | C5: =COUNTIFS(功能开发计划!A:A,A5,功能开发计划!E:E,"已发布") | D5: =IFERROR(C5/B5,0) | E5: =COUNTIFS(功能开发计划!A:A,A5,功能开发计划!G:G,"高") | F5: =SUMPRODUCT((功能开发计划!A2:A100=A5)*ISNUMBER(功能开发计划!I2:I100)*功能开发计划!I2:I100)
A6: 钉钉 OA 集成 | B6: =COUNTIF(功能开发计划!A:A,A6) | C6: =COUNTIFS(功能开发计划!A:A,A6,功能开发计划!E:E,"已发布") | D6: =IFERROR(C6/B6,0) | E6: =COUNTIFS(功能开发计划!A:A,A6,功能开发计划!G:G,"高") | F6: =SUMPRODUCT((功能开发计划!A2:A100=A6)*ISNUMBER(功能开发计划!I2:I100)*功能开发计划!I2:I100)
A7: gh-ost 无锁 DDL | B7: =COUNTIF(功能开发计划!A:A,A7) | C7: =COUNTIFS(功能开发计划!A:A,A7,功能开发计划!E:E,"已发布") | D7: =IFERROR(C7/B7,0) | E7: =COUNTIFS(功能开发计划!A:A,A7,功能开发计划!G:G,"高") | F7: =SUMPRODUCT((功能开发计划!A2:A100=A7)*ISNUMBER(功能开发计划!I2:I100)*功能开发计划!I2:I100)
A8: 收尾 | B8: =COUNTIF(功能开发计划!A:A,A8) | C8: =COUNTIFS(功能开发计划!A:A,A8,功能开发计划!E:E,"已发布") | D8: =IFERROR(C8/B8,0) | E8: =COUNTIFS(功能开发计划!A:A,A8,功能开发计划!G:G,"高") | F8: =SUMPRODUCT((功能开发计划!A2:A100=A8)*ISNUMBER(功能开发计划!I2:I100)*功能开发计划!I2:I100)
A9: 合计 | B9: =SUM(B5:B8) | C9: =SUM(C5:C8) | D9: =IFERROR(C9/B9,0) | E9: =SUM(E5:E8) | F9: =SUM(F5:F8)
A11: 整体完成率 | B11: =TEXT(C9,"0")&"/"&TEXT(B9,"0")&" ("&TEXT(D9*100,"0.0")&"%)"
A12: 总投入人天（已交付） | B12: =SUMPRODUCT((功能开发计划!E2:E100="已发布")*ISNUMBER(功能开发计划!I2:I100)*功能开发计划!I2:I100)

Sheet 按风险等级
A1: 按风险等级
A3: 风险等级 | B3: 数量（公式） | C3: 涉及子项目
A4: 高 | B4: =COUNTIF(功能开发计划!G:G,"高") | C4: =_xlfn.TEXTJOIN("；",TRUE,IF(功能开发计划!G2:G100="高",功能开发计划!B2:B100,""))
A5: 中 | B5: =COUNTIF(功能开发计划!G:G,"中") | C5: =_xlfn.TEXTJOIN("；",TRUE,IF(功能开发计划!G2:G100="中",功能开发计划!B2:B100,""))
A6: 低 | B6: =COUNTIF(功能开发计划!G:G,"低") | C6: =_xlfn.TEXTJOIN("；",TRUE,IF(功能开发计划!G2:G100="低",功能开发计划!B2:B100,""))

Sheet 按负责人
A1: 按负责人
A3: 负责人 | B3: 已交付 | C3: 待办 | D3: 总投入人天（已交付）
A4: mavis | B4: =COUNTIFS(功能开发计划!H:H,"mavis",功能开发计划!E:E,"已发布") | C4: =COUNTIFS(功能开发计划!H:H,"mavis",功能开发计划!E:E,"待办") | D4: =SUMPRODUCT((功能开发计划!H2:H100="mavis")*(功能开发计划!E2:E100="已发布")*ISNUMBER(功能开发计划!I2:I100)*功能开发计划!I2:I100)
A5: 阿达叔叔 | B5: =COUNTIFS(功能开发计划!H:H,"阿达叔叔",功能开发计划!E:E,"已发布") | C5: =COUNTIFS(功能开发计划!H:H,"阿达叔叔",功能开发计划!E:E,"待办") | D5: =SUMPRODUCT((功能开发计划!H2:H100="阿达叔叔")*(功能开发计划!E2:E100="已发布")*ISNUMBER(功能开发计划!I2:I100)*功能开发计划!I2:I100)
